<?xml version="1.0" ?>
<sdf version="1.5">
  <model name="turtlebot3_burger">
    <pose>0.0 0.0 0.0 0.0 0.0 0.0</pose>

    <link name="base_footprint">
      <inertial>
        <inertia>
          <ixx>0.0000001</ixx>
          <ixy>0.0</ixy>
          <ixz>0.0</ixz>
          <iyy>0.0000001</iyy>
          <iyz>0.0</iyz>
          <izz>0.0000001</izz>
        </inertia>
        <mass>0.0001</mass>
      </inertial>
    </link>

    <link name="base_link">
      <inertial>
        <pose>0 0 0 0 0 0</pose>
        <inertia>
          <ixx>0.1</ixx>
          <ixy>0.0</ixy>
          <ixz>0.0</ixz>
          <iyy>0.1</iyy>
          <iyz>0.0</iyz>
          <izz>0.1</izz>
        </inertia>
        <mass>5.0</mass>
      </inertial>

      <collision name="base_collision">
        <pose>0 0 0.055 0 0 0</pose>
        <geometry>
          <box>
            <size>0.225 0.145 0.11</size>
          </box>
        </geometry>
      </collision>

      <visual name="base_visual">
        <pose>0 0 0.055 0 0 0</pose>
        <geometry>
          <box>
            <size>0.225 0.145 0.11</size>
          </box>
        </geometry>
        <material>
          <ambient>0.8 0.8 0.8 1</ambient>
          <diffuse>0.8 0.8 0.8 1</diffuse>
          <specular>0 0 0 0</specular>
          <emissive>0 0 0 1</emissive>
        </material>
      </visual>
    </link>

    <link name="imu_link">
      <inertial>
        <inertia>
          <ixx>0.0000001</ixx>
          <ixy>0.0</ixy>
          <ixz>0.0</ixz>
          <iyy>0.0000001</iyy>
          <iyz>0.0</iyz>
          <izz>0.0000001</izz>
        </inertia>
        <mass>0.01</mass>
      </inertial>

      <sensor name="tb3_imu" type="imu">
        <always_on>1</always_on>
        <update_rate>50</update_rate>
        <visualize>true</visualize>
        <topic>imu</topic>
        <enable_metrics>true</enable_metrics>
        <gz_frame_id>imu_link</gz_frame_id>
      </sensor>
    </link>

    <link name="base_scan">
      <inertial>
        <pose>0 0 0.055 0 0 0</pose>
        <inertia>
          <ixx>0.001</ixx>
          <ixy>0.000</ixy>
          <ixz>0.000</ixz>
          <iyy>0.001</iyy>
          <iyz>0.000</iyz>
          <izz>0.001</izz>
        </inertia>
        <mass>0.2</mass>
      </inertial>

      <collision name="lidar_sensor_collision">
        <pose>0 0 0.055 0 0 0</pose>
        <geometry>
          <cylinder>
            <radius>0.03</radius>
            <length>0.05</length>
          </cylinder>
        </geometry>
      </collision>

      <visual name="lidar_sensor_visual">
        <pose>0 0 0.055 0 0 0</pose>
        <geometry>
          <cylinder>
            <radius>0.03</radius>
            <length>0.05</length>
          </cylinder>
        </geometry>
        <material>
          <ambient>0 0 0.8 1</ambient>
          <diffuse>0 0 0.8 1</diffuse>
          <specular>0 0 0 0</specular>
          <emissive>0 0 0 1</emissive>
        </material>
      </visual>

      <sensor name="hls_lfcd_lds" type="gpu_lidar">
        <always_on>true</always_on>
        <visualize>true</visualize>
        <pose>0 0 0.055 0 0 0</pose>
        <update_rate>5</update_rate>
        <topic>scan</topic>
        <gz_frame_id>base_scan</gz_frame_id>
        <lidar>
          <scan>
            <horizontal>
              <samples>360</samples>
              <resolution>1.000000</resolution>
              <min_angle>-3.14159</min_angle>
              <max_angle>3.14159</max_angle>
            </horizontal>
          </scan>
          <range>
            <min>0.2</min>
            <max>30.0</max>
            <resolution>0.01</resolution>
          </range>
          <noise>
            <type>gaussian</type>
            <mean>0.0</mean>
            <stddev>0.01</stddev>
          </noise>
        </lidar>
      </sensor>
    </link>

    <link name="wheel_left_link">
      <inertial>
        <pose>0.08 0.08 -0.060 -1.5708 0 0</pose>
        <inertia>
          <ixx>0.01</ixx>
          <ixy>0.0</ixy>
          <ixz>0.0</ixz>
          <iyy>0.01</iyy>
          <iyz>0.0</iyz>
          <izz>0.01</izz>
        </inertia>
        <mass>0.5</mass>
      </inertial>

      <collision name="wheel_left_collision">
        <pose>0.08 0.08 -0.060 -1.5708 0 0</pose>
        <geometry>
          <cylinder>
            <radius>0.035</radius>
            <length>0.017</length>
          </cylinder>
        </geometry>
        <surface>
          <friction>
            <ode>
              <mu>1.0</mu>
              <mu2>1.0</mu2>
              <fdir1>1 0 0</fdir1>
              <slip1>0.0</slip1> 
              <slip2>0.0</slip2> 
            </ode>
          </friction>
          <contact>
            <ode>
              <kp>500000.0</kp>
              <kd>10.0</kd>
              <max_vel>0.1</max_vel>
              <min_depth>0.001</min_depth>
            </ode>
          </contact>
        </surface>
      </collision>

      <visual name="wheel_left_visual">
        <pose>0.08 0.08 -0.060 -1.5708 0 0</pose>
        <geometry>
          <cylinder>
            <radius>0.035</radius>
            <length>0.017</length>
          </cylinder>
        </geometry>
        <material>
          <ambient>0 0 0 1</ambient>
          <diffuse>0 0 0 1</diffuse>
          <specular>0 0 0 0</specular>
          <emissive>0 0 0 1</emissive>
        </material>
      </visual>
    </link>

    <link name="wheel_right_link">
      <inertial>
        <pose>0.08 -0.08 -0.060 -1.5708 0 0</pose>
        <inertia>
          <ixx>0.01</ixx>
          <ixy>0.0</ixy>
          <ixz>0.0</ixz>
          <iyy>0.01</iyy>
          <iyz>0.0</iyz>
          <izz>0.01</izz>
        </inertia>
        <mass>0.5</mass>
      </inertial>

      <collision name="wheel_right_collision">
        <pose>0.08 -0.08 -0.060 -1.5708 0 0</pose>
        <geometry>
          <cylinder>
            <radius>0.035</radius>
            <length>0.017</length>
          </cylinder>
        </geometry>
        <surface>
          <friction>
            <ode>
              <mu>1.0</mu>
              <mu2>1.0</mu2>
              <fdir1>1 0 0</fdir1>
              <slip1>0.0</slip1> 
              <slip2>0.0</slip2> 
            </ode>
          </friction>
          <contact>
            <ode>
              <kp>500000.0</kp>
              <kd>10.0</kd>
              <max_vel>0.1</max_vel>
              <min_depth>0.001</min_depth>
            </ode>
          </contact>
        </surface>
      </collision>

      <visual name="wheel_right_visual">
        <pose>0.08 -0.08 -0.060 -1.5708 0 0</pose>
        <geometry>
          <cylinder>
            <radius>0.035</radius>
            <length>0.017</length>
          </cylinder>
        </geometry>
        <material>
          <ambient>0 0 0 1</ambient>
          <diffuse>0 0 0 1</diffuse>
          <specular>0 0 0 0</specular>
          <emissive>0 0 0 1</emissive>
        </material>
      </visual>
    </link>

    <!-- Additional rear left wheel (fixed) -->
    <link name='caster_back_link'> 
      <pose>-0.08 0.08 -0.060 -1.5708 0 0</pose> 
      <inertial> 
        <mass>0.5</mass> 
        <inertia> 
          <ixx>0.01</ixx> 
          <ixy>0.000</ixy> 
          <ixz>0.000</ixz> 
          <iyy>0.01</iyy> 
          <iyz>0.000</iyz> 
          <izz>0.01</izz> 
        </inertia> 
      </inertial> 
      <collision name='collision'> 
        <geometry> 
          <cylinder>
            <radius>0.035</radius>
            <length>0.017</length>
          </cylinder>
        </geometry> 
        <surface> 
          <contact> 
            <ode> 
              <soft_cfm>0</soft_cfm> 
              <soft_erp>0.2</soft_erp> 
              <kp>1e+7</kp> 
              <kd>100</kd> 
              <max_vel>1.0</max_vel> 
              <min_depth>0.001</min_depth> 
            </ode> 
          </contact>
          <friction>
            <ode>
              <mu>0.1</mu>
              <mu2>0.01</mu2>
              <fdir1>1 0 0</fdir1>
              <slip1>0.5</slip1> 
              <slip2>0.9</slip2> 
            </ode>
          </friction>
        </surface> 
      </collision>
      <visual name="visual">
        <geometry>
          <cylinder>
            <radius>0.035</radius>
            <length>0.017</length>
          </cylinder>
        </geometry>
        <material>
          <ambient>0 0 0 1</ambient>
          <diffuse>0 0 0 1</diffuse>
          <specular>0 0 0 0</specular>
          <emissive>0 0 0 1</emissive>
        </material>
      </visual>
    </link> 

    <!-- Additional rear right wheel (fixed) -->
    <link name='wheel_right_b_link'> 
      <pose>-0.08 -0.08 -0.060 -1.5708 0 0</pose> 
      <inertial> 
        <mass>0.5</mass> 
        <inertia> 
          <ixx>0.01</ixx> 
          <ixy>0.000</ixy> 
          <ixz>0.000</ixz> 
          <iyy>0.01</iyy> 
          <iyz>0.000</iyz> 
          <izz>0.01</izz> 
        </inertia> 
      </inertial> 
      <collision name='collision'> 
        <geometry> 
          <cylinder>
            <radius>0.035</radius>
            <length>0.017</length>
          </cylinder>
        </geometry> 
        <surface> 
          <contact> 
            <ode> 
              <soft_cfm>0</soft_cfm> 
              <soft_erp>0.2</soft_erp> 
              <kp>1e+7</kp> 
              <kd>100</kd> 
              <max_vel>1.0</max_vel> 
              <min_depth>0.001</min_depth> 
            </ode> 
          </contact>
          <friction>
            <ode>
              <mu>0.1</mu>
              <mu2>0.01</mu2>
              <fdir1>1 0 0</fdir1>
              <slip1>0.5</slip1> 
              <slip2>0.9</slip2> 
            </ode>
          </friction>
        </surface> 
      </collision>
      <visual name="visual">
        <geometry>
          <cylinder>
            <radius>0.035</radius>
            <length>0.017</length>
          </cylinder>
        </geometry>
        <material>
          <ambient>0 0 0 1</ambient>
          <diffuse>0 0 0 1</diffuse>
          <specular>0 0 0 0</specular>
          <emissive>0 0 0 1</emissive>
        </material>
      </visual>
    </link> 

    <link name="camera_link">
      <inertial>
        <pose>0.1125 0 0 0 0 0</pose>
        <inertia>
          <ixx>0.001</ixx>
          <ixy>0.0</ixy>
          <ixz>0.0</ixz>
          <iyy>0.001</iyy>
          <iyz>0.0</iyz>
          <izz>0.001</izz>
        </inertia>
        <mass>0.1</mass>
      </inertial>

      <collision name="camera_collision">
        <pose>0.1125 0 0 0 0 0</pose>
        <geometry>
          <box>
            <size>0.085 0.025 0.015</size>
          </box>
        </geometry>
      </collision>

      <visual name="camera_visual">
        <pose>0.1125 0 0 0 0 0</pose>
        <geometry>
          <box>
            <size>0.085 0.025 0.015</size>
          </box>
        </geometry>
        <material>
          <ambient>1 0 0 1</ambient>
          <diffuse>1 0 0 1</diffuse>
          <specular>0 0 0 0</specular>
          <emissive>0 0 0 1</emissive>
        </material>
      </visual>

      <sensor name="camera" type="camera">
        <always_on>true</always_on>
        <visualize>true</visualize>
        <update_rate>30</update_rate>
        <topic>camera/image_raw</topic>
        <gz_frame_id>camera_link</gz_frame_id>
        <camera name="intel_realsense_r200">
          <camera_info_topic>camera/camera_info</camera_info_topic>
          <optical_frame_id>camera_link_optical</optical_frame_id>
          <horizontal_fov>1.3962634</horizontal_fov>
          <image>
            <width>800</width>
            <height>600</height>
            <format>R8G8B8</format>
          </image>
          <clip>
            <near>0.02</near>
            <far>300</far>
          </clip>
          <noise>
            <type>gaussian</type>
            <mean>0.0</mean>
            <stddev>0.007</stddev>
          </noise>
        </camera>
      </sensor>
    </link>   

    <!-- JOINTS -->
    <joint name="base_joint" type="fixed">
      <parent>base_footprint</parent>
      <child>base_link</child>
      <pose>0.0 0.0 0.035 0 0 0</pose>
    </joint>

    <joint name="wheel_left_joint" type="revolute">
      <parent>base_link</parent>
      <child>wheel_left_link</child>
      <pose>0.08 0.08 -0.060 -1.5708 0 0</pose>
      <axis>
        <xyz>0 0 1</xyz>
        <limit>
          <effort>100</effort>
          <velocity>10</velocity>
          <lower>-inf</lower>
          <upper>inf</upper>
        </limit>
        <dynamics>
          <damping>1</damping>
          <friction>1</friction>
          <spring_reference>0</spring_reference>
          <spring_stiffness>0</spring_stiffness>
        </dynamics>
      </axis>
    </joint>

    <joint name="wheel_right_joint" type="revolute">
      <parent>base_link</parent>
      <child>wheel_right_link</child>
      <pose>0.08 -0.08 -0.060 -1.5708 0 0</pose>
      <axis>
        <xyz>0 0 1</xyz>
        <limit>
          <effort>100</effort>
          <velocity>10</velocity>
          <lower>-inf</lower>
          <upper>inf</upper>
        </limit>
        <dynamics>
          <damping>1</damping>
          <friction>1</friction>
          <spring_reference>0</spring_reference>
          <spring_stiffness>0</spring_stiffness>
        </dynamics>
      </axis>
    </joint>

    <!-- Fixed rear left wheel joint -->
    <joint name='caster_back_joint' type='fixed'> 
      <parent>base_link</parent> 
      <child>caster_back_link</child> 
      <pose>-0.08 0.08 -0.060 0 0 0</pose>
    </joint> 

    <!-- Fixed rear right wheel joint -->
    <joint name='wheel_right_b_joint' type='fixed'> 
      <parent>base_link</parent> 
      <child>wheel_right_b_link</child> 
      <pose>-0.08 -0.08 -0.060 0 0 0</pose>
    </joint> 

    <joint name="imu_joint" type="fixed">
      <parent>base_link</parent>
      <child>imu_link</child>
      <pose>0 0 0.055 0 0 0</pose>
      <axis>
        <xyz>0 0 1</xyz>
      </axis>
    </joint>

    <joint name="lidar_joint" type="fixed">
      <parent>base_link</parent>
      <child>base_scan</child>
      <pose>0 0 0.055 0 0 0</pose>
      <axis>
        <xyz>0 0 1</xyz>
      </axis>
    </joint>

    <joint name="camera_joint" type="fixed">
      <parent>base_link</parent>
      <child>camera_link</child>
      <pose>0.1125 0 0 0 0 0</pose>
      <axis>
        <xyz>0 1 0</xyz>
      </axis>
    </joint>

    <!-- Differential Drive Plugin -->
    <plugin filename="gz-sim-diff-drive-system" name="gz::sim::systems::DiffDrive">
      <!-- wheels -->
      <left_joint>wheel_left_joint</left_joint>
      <right_joint>wheel_right_joint</right_joint>

      <!-- kinematics -->
      <wheel_separation>0.16</wheel_separation>
      <wheel_radius>0.035</wheel_radius>

      <!-- Control gains and limits -->
      <max_velocity>10.0</max_velocity>
      <max_linear_acceleration>100.0</max_linear_acceleration>
      <min_linear_acceleration>-1.0</min_linear_acceleration>
      <max_angular_acceleration>2.0</max_angular_acceleration>
      <min_angular_acceleration>-2.0</min_angular_acceleration>
      <max_linear_velocity>10.0</max_linear_velocity>
      <min_linear_velocity>-0.2</min_linear_velocity>
      <max_angular_velocity>1.0</max_angular_velocity>
      <min_angular_velocity>-1.0</min_angular_velocity>

      <topic>cmd_vel</topic>

      <odom_topic>odom</odom_topic>
      <frame_id>odom</frame_id>
      <tf_topic>tf</tf_topic>
      <odom_publisher_frequency>100</odom_publisher_frequency>
      <child_frame_id>base_footprint</child_frame_id>

    </plugin>

    <plugin filename="gz-sim-joint-state-publisher-system"
      name="gz::sim::systems::JointStatePublisher">
      <topic>joint_states</topic>
      <update_rate>100</update_rate>
      <joint_name>wheel_left_joint</joint_name>
      <joint_name>wheel_right_joint</joint_name>
    </plugin>    

  </model>
</sdf>
